Workbook

Sheet 0_Synthèse
A1: Matrice de couverture et de transformation exhaustive
A2: Corpus de Marie-Noëlle Lopez × cahier des charges validé — version de travail traçable
A4: Indicateur | B4: Valeur | D4: Mode d’emploi
A5: Documents sources de Marie-Noëlle | B5: 11 | D5: La feuille 2_Matrice exhaustive constitue la table de référence : chaque paragraphe, titre ou ligne de tableau du corpus possède un identifiant unique, son texte exact, sa séquence cible et son traitement. La feuille 3_Architecture montre la recomposition en six séquences. La feuille 4_Exigences relie le cahier des charges aux preuves attendues. La feuille 5_Contrôles permet de vérifier qu’aucune source n’a été perdue.
A6: Blocs textuels inventoriés | B6: 1079
A7: Mots source inventoriés | B7: 20551
A8: Exigences du cahier des charges tracées | B8: 204
A9: Principe de couverture | B9: 100 % des blocs sont affectés à une cible et à un traitement
A12: Légende des transformations
A13: Statut | B13: Signification | C13: Règle de travail
A14: Texte source conservé | B14: Le contenu est intégré au mot près. | C14: Seuls le découpage d’écran et la médiatisation changent.
A15: Déplacement sans perte | B15: Le bloc change de module ou de séquence. | C15: L’intitulé et le contenu restent traçables.
A16: Transformation de forme | B16: Tableau, fiche ou liste devient un composant numérique. | C16: Aucune information source ne disparaît.
A17: Adaptation légère à valider | B17: La consigne est ajustée pour l’UX ou l’accessibilité. | C17: Marie-Noëlle valide la microcopie finale.
A18: Adaptation obligatoire | B18: Une règle source contredit le cahier des charges. | C18: La source reste visible dans la matrice ; le produit applique l’arbitrage supérieur.
A19: Validation documentaire | B19: La référence ou le fondement doit être vérifié. | C19: Aucune référence n’est inventée.

Sheet 1_Sources
A1: Inventaire du corpus
A2: Contrôle quantitatif des documents fournis par Marie-Noëlle
A4: Code | B4: Document source | C4: Blocs extraits | D4: Mots extraits | E4: Blocs présents dans la matrice | F4: Écart | G4: Statut
A5: M0 | B5: MODULE 0 — MON AUTO-POSITIONNEMENT DE MANAGER.docx | C5: 77 | D5: 1290 | E5: 77 | F5: 0 | G5: Couverture complète
A6: M1 | B6: MODULE 1 — COMPRENDRE MON RÔLE DE MANAGER ÉLU DU CONGRES .docx | C6: 124 | D6: 2849 | E6: 124 | F6: 0 | G6: Couverture complète
A7: M2 | B7: MODULE 2 — CONSTITUER LA BONNE ÉQUIPE.docx | C7: 121 | D7: 2321 | E7: 121 | F7: 0 | G7: Couverture complète
A8: M3 | B8: MODULE 3 — DONNER DU CAP SANS TOUT CONTRÔLER.docx | C8: 120 | D8: 2415 | E8: 120 | F8: 0 | G8: Couverture complète
A9: M4 | B9: MODULE 4 — COMMUNIQUER COMME MANAGER .docx | C9: 165 | D9: 3742 | E9: 165 | F9: 0 | G9: Couverture complète
A10: M5 | B10: MODULE 5 — GÉRER LES TENSIONS.docx | C10: 157 | D10: 2923 | E10: 157 | F10: 0 | G10: Couverture complète
A11: M6 | B11: MODULE 6 — MON AUTORITÉ AJUSTÉE.docx | C11: 138 | D11: 2172 | E11: 138 | F11: 0 | G11: Couverture complète
A12: M7 | B12: MODULE 7 — MON PLAN D'ACTION DE MANDAT.docx | C12: 75 | D12: 1310 | E12: 75 | F12: 0 | G12: Couverture complète
A13: A4 | B13: Z - Annexe Module 4 — Fiche « Les mots qui piquent _ les mots qui soutiennent ».docx | C13: 34 | D13: 507 | E13: 34 | F13: 0 | G13: Couverture complète
A14: A5 | B14: Z - Annexe Module 5 — Deux grilles de questions puissantes.docx | C14: 32 | D14: 407 | E14: 32 | F14: 0 | G14: Couverture complète
A15: BIENVENUE | B15: _ Bienvenue dans votre parcours.docx | C15: 36 | D15: 615 | E15: 36 | F15: 0 | G15: Couverture complète

Sheet 2_Matrice exhaustive
A1: Matrice exhaustive — corpus de Marie-Noëlle
A2: Une ligne par bloc source ; aucune suppression implicite. Filtrer par source, séquence cible, fonction ou statut.
A4: ID | B4: Source | C4: Module source | D4: Ordre | E4: Localisation source | F4: Type de bloc | G4: Texte source exact | H4: Séquence cible | I4: Fonction pédagogique | J4: Transformation proposée | K4: Statut de transformation | L4: Fidélité attendue | M4: Validation
A5: MNL-0001 | B5: MODULE 0 — MON AUTO-POSITIONNEMENT DE MANAGER.docx | C5: M0 | D5: 1 | E5: MODULE 0 — MON AUTO-POSITIONNEMENT DE MANAGER | F5: Titre | G5: MODULE 0 — MON AUTO-POSITIONNEMENT DE MANAGER | H5: Entrée + S6 — Comparaison finale | I5: Positionnement / boucle réflexive | J5: Conserver les formulations ; intégrer au positionnement initial ou à la comparaison finale selon la cible. | K5: Texte source conservé + orchestration | L5: Au mot près | M5: Contrôle IFAP
A6: MNL-0002 | B6: MODULE 0 — MON AUTO-POSITIONNEMENT DE MANAGER.docx | C6: M0 | D6: 2 | E6: Votre photographie de départ | F6: Titre | G6: Votre photographie de départ | H6: Entrée + S6 — Comparaison finale | I6: Positionnement / boucle réflexive | J6: Conserver les formulations ; intégrer au positionnement initial ou à la comparaison finale selon la cible. | K6: Texte source conservé + orchestration | L6: Au mot près | M6: Contrôle IFAP
A7: MNL-0003 | B7: MODULE 0 — MON AUTO-POSITIONNEMENT DE MANAGER.docx | C7: M0 | D7: 3 | E7: Fiche signalétique | F7: Titre | G7: Fiche signalétique | H7: Entrée + S6 — Comparaison finale | I7: Métadonnée de conception | J7: Conserver dans les spécifications ; ne pas afficher telle quelle à l’apprenant. | K7: Adaptation nécessaire | L7: Source visible ; adaptation tracée | M7: Contrôle IFAP
A8: MNL-0004 | B8: MODULE 0 — MON AUTO-POSITIONNEMENT DE MANAGER.docx | C8: M0 | D8: 4 | E8: Fiche signalétique | F8: Ligne de tableau | G8: Élément | Détail | H8: Entrée + S6 — Comparaison finale | I8: Métadonnée de conception | J8: Conserver dans les spécifications ; ne pas afficher telle quelle à l’apprenant. | K8: Adaptation nécessaire | L8: Source visible ; adaptation tracée | M8: Contrôle IFAP
A9: MNL-0005 | B9: MODULE 0 — MON AUTO-POSITIONNEMENT DE MANAGER.docx | C9: M0 | D9: 5 | E9: Fiche signalétique | F9: Ligne de tableau | G9: Durée totale | 30 minutes maximum | H9: Entrée + S6 — Comparaison finale | I9: Métadonnée de conception | J9: Conserver dans les spécifications ; ne pas afficher telle quelle à l’apprenant. | K9: Adaptation nécessaire | L9: Source visible ; adaptation tracée | M9: Contrôle IFAP
A10: MNL-0006 | B10: MODULE 0 — MON AUTO-POSITIONNEMENT DE MANAGER.docx | C10: M0 | D10: 6 | E10: Fiche signalétique | F10: Ligne de tableau | G10: Niveau atteint | Diagnostic | H10: Entrée + S6 — Comparaison finale | I10: Métadonnée de conception | J10: Conserver dans les spécifications ; ne pas afficher telle quelle à l’apprenant. | K10: Adaptation nécessaire | L10: Source visible ; adaptation tracée | M10: Contrôle IFAP
A11: MNL-0007 | B11: MODULE 0 — MON AUTO-POSITIONNEMENT DE MANAGER.docx | C11: M0 | D11: 7 | E11: Fiche signalétique | F11: Ligne de tableau | G11: Prérequis | Aucun — module d'entrée dans le parcours | H11: Entrée + S6 — Comparaison finale | I11: Métadonnée de conception | J11: Conserver dans les spécifications ; ne pas afficher telle quelle à l’apprenant. | K11: Adaptation nécessaire | L11: Source visible ; adaptation tracée | M11: Contrôle IFAP
A12: MNL-0008 | B12: MODULE 0 — MON AUTO-POSITIONNEMENT DE MANAGER.docx | C12: M0 | D12: 8 | E12: Fiche signalétique | F12: Ligne de tableau | G12: Indicateur mesurable | Score de profil managérial à T0 (référence pour la mesure finale, Module 7) | H12: Entrée + S6 — Comparaison finale | I12: Métadonnée de conception | J12: Conserver dans les spécifications ; ne pas afficher telle quelle à l’apprenant. | K12: Adaptation nécessaire | L12: Source visible ; adaptation tracée | M12: Contrôle IFAP
A13: MNL-0009 | B13: MODULE 0 — MON AUTO-POSITIONNEMENT DE MANAGER.docx | C13: M0 | D13: 9 | E13: Fiche signalétique | F13: Ligne de tableau | G13: Condition de passage | Complétion de l'auto-positionnement — pas de bonne ou de mauvaise réponse ici, seule la complétude ouvre l'accès au Module 1 | H13: Entrée + S6 — Comparaison finale | I13: Métadonnée de conception | J13: Conserver dans les spécifications ; ne pas afficher telle quelle à l’apprenant. | K13: Adaptation nécessaire | L13: Source visible ; adaptation tracée | M13: Contrôle IFAP
A14: MNL-0010 | B14: MODULE 0 — MON AUTO-POSITIONNEMENT DE MANAGER.docx | C14: M0 | D14: 10 | E14: Fiche signalétique | F14: Ligne de tableau | G14: Objectifs pédagogiques — à l'issue du module, l'apprenant(e) est capable de : Se situer sur les grandes dimensions qui seront travaillées tout au long du parcours ; Formuler une intention personnelle claire pour la suite de son parcours ; Comprendre la logique de progression du parcours, et ce qui l'attend module après module. | H14: Entrée + S6 — Comparaison finale | I14: Métadonnée de conception | J14: Conserver dans les spécifications ; ne pas afficher telle quelle à l’apprenant. | K14: Adaptation nécessaire | L14: Source visible ; adaptation tracée | M14: Contrôle IFAP
A15: MNL-0011 | B15: MODULE 0 — MON AUTO-POSITIONNEMENT DE MANAGER.docx | C15: M0 | D15: 11 | E15: Séquençage (30 min) | F15: Titre | G15: Séquençage (30 min) | H15: Entrée + S6 — Comparaison finale | I15: Métadonnée de conception | J15: Conserver dans les spécifications ; ne pas afficher telle quelle à l’apprenant. | K15: Adaptation nécessaire | L15: Source visible ; adaptation tracée | M15: Contrôle IFAP
A16: MNL-0012 | B16: MODULE 0 — MON AUTO-POSITIONNEMENT DE MANAGER.docx | C16: M0 | D16: 12 | E16: Séquençage (30 min) | F16: Ligne de tableau | G16: # | Étape | Durée | Modalité | H16: Entrée + S6 — Comparaison finale | I16: Métadonnée de conception | J16: Conserver dans les spécifications ; ne pas afficher telle quelle à l’apprenant. | K16: Adaptation nécessaire | L16: Source visible ; adaptation tracée | M16: Contrôle IFAP
... A981: MNL-0977 | B981: MODULE 7 — MON PLAN D'ACTION DE MANDAT.docx | C981: M7 | D981: 75 | E981: 6. Pour conclure ce parcours | F981: Paragraphe | G981: "Le parcours se termine ici. Votre plan, lui, commence maintenant." | H981: S6 — Faire évoluer ma pratique | I981: Apport / message pédagogique | J981: Intégrer au mot près dans le premier prototype exhaustif ; segmenter en écrans ou révélations progressives sans réécriture de fond. | K981: Texte source conservé | L981: Au mot près | M981: Contrôle IFAP
A982: MNL-0978 | B982: Z - Annexe Module 4 — Fiche « Les mots qui piquent _ les mots qui soutiennent ».docx | C982: A4 | D982: 1 | F982: Ligne de tableau | G982: Annexe Module 4 — Fiche « Les mots qui piquent / les mots qui soutiennent | H982: S3 — Faire comprendre ce que j’attends | I982: Apport structuré | J982: Conserver chaque entrée ; restituer en tableau, cartes, accordéon ou grille responsive selon l’usage. | K982: Transformation de forme | L982: Source visible ; adaptation tracée | M982: Contrôle IFAP
A983: MNL-0979 | B983: Z - Annexe Module 4 — Fiche « Les mots qui piquent _ les mots qui soutiennent ».docx | C983: A4 | D983: 2 | F983: Paragraphe | G983: Fiche de référence, hors minutage des 45 min — accessible à tout moment depuis le module (renvoi possible depuis la section 3.2), et réutilisable telle quelle comme pense-bête imprimable. | H983: S3 — Faire comprendre ce que j’attends | I983: Référence / fondement | J983: Conserver la formulation et rendre la source visible au moment utile ; vérifier la référence complète avant diffusion. | K983: Validation documentaire | L983: Source visible ; adaptation tracée | M983: Marie-Noëlle
A984: MNL-0980 | B984: Z - Annexe Module 4 — Fiche « Les mots qui piquent _ les mots qui soutiennent ».docx | C984: A4 | D984: 3 | F984: Paragraphe | G984: Comment l'utiliser — Avant un échange sensible, un coup d'œil suffit : repérer si la formulation prévue appartient à la colonne de gauche, et si oui, piocher l'équivalent à droite. | H984: S3 — Faire comprendre ce que j’attends | I984: Apport / message pédagogique | J984: Intégrer au mot près dans le premier prototype exhaustif ; segmenter en écrans ou révélations progressives sans réécriture de fond. | K984: Texte source conservé | L984: Au mot près | M984: Contrôle IFAP
A985: MNL-0981 | B985: Z - Annexe Module 4 — Fiche « Les mots qui piquent _ les mots qui soutiennent ».docx | C985: A4 | D985: 4 | E985: Pour donner une consigne | F985: Titre | G985: Pour donner une consigne | H985: S3 — Faire comprendre ce que j’attends | I985: Activité / consigne | J985: Conserver le sens et le texte expert ; adapter uniquement la microcopie aux contraintes d’accessibilité et d’interaction. | K985: Adaptation légère à valider | L985: Source visible ; adaptation tracée | M985: Marie-Noëlle
A986: MNL-0982 | B986: Z - Annexe Module 4 — Fiche « Les mots qui piquent _ les mots qui soutiennent ».docx | C986: A4 | D986: 5 | E986: Pour donner une consigne | F986: Ligne de tableau | G986: Ça ferme | Ça ouvre | H986: S3 — Faire comprendre ce que j’attends | I986: Activité / consigne | J986: Conserver le sens et le texte expert ; adapter uniquement la microcopie aux contraintes d’accessibilité et d’interaction. | K986: Adaptation légère à valider | L986: Source visible ; adaptation tracée | M986: Marie-Noëlle
A987: MNL-0983 | B987: Z - Annexe Module 4 — Fiche « Les mots qui piquent _ les mots qui soutiennent ».docx | C987: A4 | D987: 6 | E987: Pour donner une consigne | F987: Ligne de tableau | G987: « Débrouillez-vous. » | « Voici ce dont vous avez besoin pour démarrer : … » | H987: S3 — Faire comprendre ce que j’attends | I987: Activité / consigne | J987: Conserver le sens et le texte expert ; adapter uniquement la microcopie aux contraintes d’accessibilité et d’interaction. | K987: Adaptation légère à valider | L987: Source visible ; adaptation tracée | M987: Marie-Noëlle
A988: MNL-0984 | B988: Z - Annexe Module 4 — Fiche « Les mots qui piquent _ les mots qui soutiennent ».docx | C988: A4 | D988: 7 | E988: Pour donner une consigne | F988: Ligne de tableau | G988: « Il faut que ça avance. » | « J'ai besoin que ce soit prêt pour [date/heure précise]. » | H988: S3 — Faire comprendre ce que j’attends | I988: Activité / consigne | J988: Conserver le sens et le texte expert ; adapter uniquement la microcopie aux contraintes d’accessibilité et d’interaction. | K988: Adaptation légère à valider | L988: Source visible ; adaptation tracée | M988: Marie-Noëlle
A989: MNL-0985 | B989: Z - Annexe Module 4 — Fiche « Les mots qui piquent _ les mots qui soutiennent ».docx | C989: A4 | D989: 8 | E989: Pour donner une consigne | F989: Ligne de tableau | G989: « C'est pas compliqué pourtant. » | « Dites-moi si un point n'est pas clair. » | H989: S3 — Faire comprendre ce que j’attends | I989: Activité / consigne | J989: Conserver le sens et le texte expert ; adapter uniquement la microcopie aux contraintes d’accessibilité et d’interaction. | K989: Adaptation légère à valider | L989: Source visible ; adaptation tracée | M989: Marie-Noëlle
A990: MNL-0986 | B990: Z - Annexe Module 4 — Fiche « Les mots qui piquent _ les mots qui soutiennent ».docx | C990: A4 | D990: 9 | E990: Pour donner une consigne | F990: Ligne de tableau | G990: « Vous auriez dû anticiper. » | « La prochaine fois, prévenons-nous plus tôt sur ce type de point. » | H990: S3 — Faire comprendre ce que j’attends | I990: Activité / consigne | J990: Conserver le sens et le texte expert ; adapter uniquement la microcopie aux contraintes d’accessibilité et d’interaction. | K990: Adaptation légère à valider | L990: Source visible ; adaptation tracée | M990: Marie-Noëlle
A991: MNL-0987 | B991: Z - Annexe Module 4 — Fiche « Les mots qui piquent _ les mots qui soutiennent ».docx | C991: A4 | D991: 10 | E991: Pour faire un retour (feedback) | F991: Titre | G991: Pour faire un retour (feedback) | H991: S4 — Faire grandir l’autonomie et l’engagement | I991: Structuration | J991: Conserver comme repère éditorial ; fusionner ou déplacer sous la séquence cible sans perdre l’intitulé source. | K991: Déplacement sans perte | L991: Au mot près | M991: Contrôle IFAP
A992: MNL-0988 | B992: Z - Annexe Module 4 — Fiche « Les mots qui piquent _ les mots qui soutiennent ».docx | C992: A4 | D992: 11 | E992: Pour faire un retour (feedback) | F992: Ligne de tableau | G992: Ça ferme | Ça ouvre | H992: S4 — Faire grandir l’autonomie et l’engagement | I992: Apport structuré | J992: Conserver chaque entrée ; restituer en tableau, cartes, accordéon ou grille responsive selon l’usage. | K992: Transformation de forme | L992: Source visible ; adaptation tracée | M992: Contrôle IFAP
A993: MNL-0989 | B993: Z - Annexe Module 4 — Fiche « Les mots qui piquent _ les mots qui soutiennent ».docx | C993: A4 | D993: 12 | E993: Pour faire un retour (feedback) | F993: Ligne de tableau | G993: « C'est mal fait. » | « Cette partie est claire ; celle-ci mérite d'être reprise. » | H993: S4 — Faire grandir l’autonomie et l’engagement | I993: Apport structuré | J993: Conserver chaque entrée ; restituer en tableau, cartes, accordéon ou grille responsive selon l’usage. | K993: Transformation de forme | L993: Source visible ; adaptation tracée | M993: Contrôle IFAP
A994: MNL-0990 | B994: Z - Annexe Module 4 — Fiche « Les mots qui piquent _ les mots qui soutiennent ».docx | C994: A4 | D994: 13 | E994: Pour faire un retour (feedback) | F994: Ligne de tableau | G994: « Vous n'y arrivez pas. » | « Voici ce qui manque pour que ce soit complet. » | H994: S4 — Faire grandir l’autonomie et l’engagement | I994: Apport structuré | J994: Conserver chaque entrée ; restituer en tableau, cartes, accordéon ou grille responsive selon l’usage. | K994: Transformation de forme | L994: Source visible ; adaptation tracée | M994: Contrôle IFAP
A995: MNL-0991 | B995: Z - Annexe Module 4 — Fiche « Les mots qui piquent _ les mots qui soutiennent ».docx | C995: A4 | D995: 14 | E995: Pour faire un retour (feedback) | F995: Ligne de tableau | G995: « Ça ne va pas du tout. » | « Voici précisément ce qui doit changer. » | H995: S4 — Faire grandir l’autonomie et l’engagement | I995: Apport structuré | J995: Conserver chaque entrée ; restituer en tableau, cartes, accordéon ou grille responsive selon l’usage. | K995: Transformation de forme | L995: Source visible ; adaptation tracée | M995: Contrôle IFAP
A996: MNL-0992 | B996: Z - Annexe Module 4 — Fiche « Les mots qui piquent _ les mots qui soutiennent ».docx | C996: A4 | D996: 15 | E996: Pour faire un retour (feedback) | F996: Ligne de tableau | G996: « Comme d'habitude… » | (à bannir — ramène toujours au passé plutôt qu'à la situation présente) | H996: S4 — Faire grandir l’autonomie et l’engagement | I996: Apport structuré | J996: Conserver chaque entrée ; restituer en tableau, cartes, accordéon ou grille responsive selon l’usage. | K996: Transformation de forme | L996: Source visible ; adaptation tracée | M996: Contrôle IFAP
... A1015: MNL-1011 | B1015: Z - Annexe Module 4 — Fiche « Les mots qui piquent _ les mots qui soutiennent ».docx | C1015: A4 | D1015: 34 | E1015: Mots et tournures à surveiller, en général | F1015: Ligne de tableau | G1015: « On verra » | Flou, laisse l'autre dans l'incertitude | Donner une échéance, même approximative | H1015: S3 — Faire comprendre ce que j’attends | I1015: Apport structuré | J1015: Conserver chaque entrée ; restituer en tableau, cartes, accordéon ou grille responsive selon l’usage. | K1015: Transformation de forme | L1015: Source visible ; adaptation tracée | M1015: Contrôle IFAP
A1016: MNL-1012 | B1016: Z - Annexe Module 5 — Deux grilles de questions puissantes.docx | C1016: A5 | D1016: 1 | F1016: Ligne de tableau | G1016: Annexe Module 5 — Deux grilles de questions puissantes | H1016: S5 — Préserver la relation dans les moments difficiles | I1016: Apport structuré | J1016: Conserver chaque entrée ; restituer en tableau, cartes, accordéon ou grille responsive selon l’usage. | K1016: Transformation de forme | L1016: Source visible ; adaptation tracée | M1016: Contrôle IFAP
A1017: MNL-1013 | B1017: Z - Annexe Module 5 — Deux grilles de questions puissantes.docx | C1017: A5 | D1017: 2 | F1017: Paragraphe | G1017: Fiche de référence, hors minutage des 35 min — accessible à tout moment depuis le module, et réutilisable telle quelle comme pense-bête avant un entretien sensible. | H1017: S5 — Préserver la relation dans les moments difficiles | I1017: Référence / fondement | J1017: Conserver la formulation et rendre la source visible au moment utile ; vérifier la référence complète avant diffusion. | K1017: Validation documentaire | L1017: Source visible ; adaptation tracée | M1017: Marie-Noëlle
A1018: MNL-1014 | B1018: Z - Annexe Module 5 — Deux grilles de questions puissantes.docx | C1018: A5 | D1018: 3 | F1018: Ligne de tableau | G1018: Grille 1 — Pour intervenir au sein de l'équipe | H1018: S5 — Préserver la relation dans les moments difficiles | I1018: Apport structuré | J1018: Conserver chaque entrée ; restituer en tableau, cartes, accordéon ou grille responsive selon l’usage. | K1018: Transformation de forme | L1018: Source visible ; adaptation tracée | M1018: Contrôle IFAP
A1019: MNL-1015 | B1019: Z - Annexe Module 5 — Deux grilles de questions puissantes.docx | C1019: A5 | D1019: 4 | F1019: Paragraphe | G1019: Avant d'intervenir, un temps pour vous seul(e) : | H1019: S5 — Préserver la relation dans les moments difficiles | I1019: Apport / message pédagogique | J1019: Intégrer au mot près dans le premier prototype exhaustif ; segmenter en écrans ou révélations progressives sans réécriture de fond. | K1019: Texte source conservé | L1019: Au mot près | M1019: Contrôle IFAP
A1020: MNL-1016 | B1020: Z - Annexe Module 5 — Deux grilles de questions puissantes.docx | C1020: A5 | D1020: 5 | F1020: Paragraphe | G1020: Qu'est-ce que j'ai observé précisément, sans interprétation ? | H1020: S5 — Préserver la relation dans les moments difficiles | I1020: Apport / message pédagogique | J1020: Intégrer au mot près dans le premier prototype exhaustif ; segmenter en écrans ou révélations progressives sans réécriture de fond. | K1020: Texte source conservé | L1020: Au mot près | M1020: Contrôle IFAP
A1021: MNL-1017 | B1021: Z - Annexe Module 5 — Deux grilles de questions puissantes.docx | C1021: A5 | D1021: 6 | F1021: Paragraphe | G1021: Ai-je déjà une idée de qui "a raison" ? Si oui, est-ce que je peux la mettre de côté pour l'instant ? | H1021: S5 — Préserver la relation dans les moments difficiles | I1021: Apport / message pédagogique | J1021: Intégrer au mot près dans le premier prototype exhaustif ; segmenter en écrans ou révélations progressives sans réécriture de fond. | K1021: Texte source conservé | L1021: Au mot près | M1021: Contrôle IFAP
A1022: MNL-1018 | B1022: Z - Annexe Module 5 — Deux grilles de questions puissantes.docx | C1022: A5 | D1022: 7 | F1022: Paragraphe | G1022: En entretien individuel, avec chaque personne séparément : | H1022: S5 — Préserver la relation dans les moments difficiles | I1022: Apport / message pédagogique | J1022: Intégrer au mot près dans le premier prototype exhaustif ; segmenter en écrans ou révélations progressives sans réécriture de fond. | K1022: Texte source conservé | L1022: Au mot près | M1022: Contrôle IFAP
A1023: MNL-1019 | B1023: Z - Annexe Module 5 — Deux grilles de questions puissantes.docx | C1023: A5 | D1023: 8 | F1023: Paragraphe | G1023: Qu'est-ce qui se passe, de votre point de vue ? | H1023: S5 — Préserver la relation dans les moments difficiles | I1023: Apport / message pédagogique | J1023: Intégrer au mot près dans le premier prototype exhaustif ; segmenter en écrans ou révélations progressives sans réécriture de fond. | K1023: Texte source conservé | L1023: Au mot près | M1023: Contrôle IFAP
...

Sheet 3_Architecture
A1: Architecture cible et transformation du corpus
A2: Les huit défis sont conservés dans un parcours continu en six séquences, précédé d’une entrée et suivi d’une feuille de route.
A4: Ordre | B4: Étape cible | C4: Défis | D4: Sources principales | E4: Sens pour l’élu | F4: Interactions structurantes | G4: Nombre de blocs affectés
A5: 0 | B5: Entrée — Bienvenue et où j’en suis aujourd’hui | C5: 8 défis annoncés | D5: Bienvenue + M0 | E5: Comprendre l’utilité du parcours, connaître le contrat pédagogique et poser un point de départ personnel. | F5: 3 questions d’ouverture ; positionnement initial ; choix de priorités sans exclure aucun défi. | G5: 113
A6: 1 | B6: S1 — Prendre ma place de manager | C6: 1 et 2 | D6: M1 + M6 | E6: Créer un cadre de travail clair au service de l’action pour laquelle l’élu a été mandaté. | F6: Cas de dossier non finalisé ; curseur d’autorité ; clarification des rôles. | G6: 262
A7: 2 | B7: S2 — Construire une équipe sur laquelle je peux m’appuyer | C7: 3 et 4 | D7: M2 | E7: Réunir les compétences utiles et donner à chacun les moyens de contribuer pleinement aux priorités du mandat. | F7: Choix de profils enrichis ; premiers jours ; check-list d’intégration. | G7: 121
A8: 3 | B8: S3 — Faire comprendre ce que j’attends | C8: 5 | D8: M4 + annexe M4 | E8: Traduire les intentions et priorités en résultats concrets et partagés. | F8: Simulateur 1 : clarification d’une demande ; boucle réflexive complète ; grille d’acquisition. | G8: 172
A9: 4 | B9: S4 — Faire grandir l’autonomie et l’engagement | C9: 6 et 7 | D9: M3 + M4 + annexe M4 | E9: Développer la capacité d’action des collaborateurs et soutenir leur engagement dans la durée. | F9: Simulateur 2 : délégation ; micromanagement ; feedback et reconnaissance ; boucle réflexive. | G9: 141
A10: 5 | B10: S5 — Préserver la relation dans les moments difficiles | C10: 8 | D10: M5 + M4 + annexes M4/M5 | E10: Transformer les difficultés en occasions de clarification, de dialogue et de progression. | F10: Simulateur 3 : régulation ; signaux faibles ; entretien ; boucle réflexive. | G10: 195
A11: 6 | B11: S6 — Faire évoluer ma pratique | C11: Synthèse des 8 défis | D11: M0 + M7 | E11: Comparer sa posture, choisir des évolutions réalistes et formaliser trois engagements. | F11: Positionnement comparatif ; maintenir/faire évoluer/expérimenter ; feuille de route PDF. | G11: 75

Sheet 4_Exigences CDC
A1: Couverture du cahier des charges
A2: Chaque exigence du cahier des charges est isolée afin de pouvoir être reliée au scénario, au prototype et à la recette.
A4: ID | B4: Section du cahier des charges | C4: Exigence / décision | D4: Cible | E4: Type | F4: Statut de couverture | G4: Preuve attendue | H4: Responsable
A5: CDC-001 | C5: CAHIER DES CHARGES PÉDAGOGIQUE ET MÉDIA | D5: Transversal | E5: Paragraphe | F5: À intégrer / contrôler | G5: Matrice corpus + scénario détaillé | H5: IFAP
A6: CDC-002 | C6: Manager ses collaborateurs en tant qu’élu | D6: Transversal | E6: Paragraphe | F6: À intégrer / contrôler | G6: Matrice corpus + scénario détaillé | H6: IFAP
A7: CDC-003 | C7: Module e-learning destiné aux élus du Congrès de la Nouvelle-Calédonie | D7: Transversal | E7: Paragraphe | F7: À intégrer / contrôler | G7: Matrice corpus + scénario détaillé | H7: IFAP
A8: CDC-004 | C8: Promesse pédagogique Donner un cap clair, organiser la coopération et exercer une autorité à la fois exigeante, humaine et ajustée. | D8: Transversal | E8: Ligne de tableau | F8: À intégrer / contrôler | G8: Matrice corpus + scénario détaillé | H8: IFAP
A9: CDC-005 | C9: Repère | Décision | D9: Transversal | E9: Ligne de tableau | F9: À intégrer / contrôler | G9: Matrice corpus + scénario détaillé | H9: IFAP
A10: CDC-006 | C10: Public | Élus du Congrès de la Nouvelle-Calédonie — mandature 2026–2031 | D10: Transversal | E10: Ligne de tableau | F10: À intégrer / contrôler | G10: Matrice corpus + scénario détaillé | H10: IFAP
A11: CDC-007 | C11: Durée cible | Environ 2 h ; exploration possible jusqu’à 2 h 30 | D11: Transversal | E11: Ligne de tableau | F11: À intégrer / contrôler | G11: Matrice corpus + scénario détaillé | H11: IFAP
A12: CDC-008 | C12: Modalité | Parcours numérique fractionnable avec reprise exacte | D12: Transversal | E12: Ligne de tableau | F12: À intégrer / contrôler | G12: Matrice corpus + scénario détaillé | H12: IFAP
A13: CDC-009 | C13: Architecture | 6 séquences continues, 8 défis personnalisés | D13: Transversal | E13: Ligne de tableau | F13: À intégrer / contrôler | G13: Matrice corpus + scénario détaillé | H13: IFAP
A14: CDC-010 | C14: Expertise | Contenus et formulations de Marie-Noëlle Lopez | D14: Transversal | E14: Ligne de tableau | F14: À intégrer / contrôler | G14: Matrice corpus + scénario détaillé | H14: IFAP
A15: CDC-011 | C15: Statut | Cahier des charges consolidé avant scénario détaillé | D15: Transversal | E15: Ligne de tableau | F15: À intégrer / contrôler | G15: Matrice corpus + scénario détaillé | H15: IFAP
A16: CDC-012 | C16: Version | v2 — 14 août 2026 — intégration de trois simulateurs managériaux | D16: S3, S4 et S5 | E16: Ligne de tableau | F16: À intégrer / contrôler | G16: Matrice corpus + scénario détaillé | H16: IFAP
A17: CDC-013 | C17: Ce document consolide les décisions prises au cours des échanges d’ingénierie. Il fixe le cadre du scénario détaillé, de la validation des situations, de la médiatisation et de la production technique. | D17: Transversal | E17: Paragraphe | F17: À intégrer / contrôler | G17: Matrice corpus + scénario détaillé | H17: IFAP
A18: CDC-014 | B18: 1. Finalité et périmètre | C18: 1. Finalité et périmètre | D18: Transversal | E18: Titre | F18: À intégrer / contrôler | G18: Matrice corpus + scénario détaillé | H18: IFAP
A19: CDC-015 | B19: 1.1 Finalité | C19: 1.1 Finalité | D19: Transversal | E19: Titre | F19: À intégrer / contrôler | G19: Matrice corpus + scénario détaillé | H19: IFAP
A20: CDC-016 | B20: 1.1 Finalité | C20: Le parcours accompagne l’élu dans l’évolution de sa posture managériale afin qu’il puisse s’appuyer sur une coopération claire, autonome et engagée au service de son mandat. Le management est traité comme une pratique de relation, de clarification et d’action, et non comme une formation aux procédures internes du Congrès. | D20: Transversal | E20: Paragraphe | F20: À intégrer / contrôler | G20: Matrice corpus + scénario détaillé | H20: IFAP
A21: CDC-017 | B21: 1.2 Périmètre | C21: 1.2 Périmètre | D21: Transversal | E21: Titre | F21: À intégrer / contrôler | G21: Matrice corpus + scénario détaillé | H21: IFAP
A22: CDC-018 | B22: 1.2 Périmètre | C22: Le parcours concerne exclusivement la posture de l’élu du Congrès dans la relation avec ses collaborateurs politiques. | D22: Transversal | E22: Liste | F22: À intégrer / contrôler | G22: Matrice corpus + scénario détaillé | H22: IFAP
A23: CDC-019 | B23: 1.2 Périmètre | C23: La double casquette éventuelle d’élu provincial et d’élu du Congrès est explicitée à l’entrée afin d’éviter les glissements de posture ou de responsabilité. | D23: Transversal | E23: Liste | F23: À intégrer / contrôler | G23: Matrice corpus + scénario détaillé | H23: IFAP
A24: CDC-020 | B24: 1.2 Périmètre | C24: Les outils, procédures internes, formalités administratives et caractéristiques techniques des fonctions ne sont pas enseignés dans ce module. | D24: Transversal | E24: Liste | F24: À intégrer / contrôler | G24: Matrice corpus + scénario détaillé | H24: IFAP
A25: CDC-021 | B25: 1.2 Périmètre | C25: Les situations sont contextualisées à la réalité du Congrès : commissions, dossiers, décisions politiques, demandes de subvention, communication, presse et groupe politique. | D25: Transversal | E25: Liste | F25: À intégrer / contrôler | G25: Matrice corpus + scénario détaillé | H25: IFAP
A26: CDC-022 | B26: 1.3 Principes rédactionnels | C26: 1.3 Principes rédactionnels | D26: Transversal | E26: Titre | F26: À intégrer / contrôler | G26: Matrice corpus + scénario détaillé | H26: IFAP
A27: CDC-023 | B27: 1.3 Principes rédactionnels | C27: Formulations positives, fluides et orientées vers les solutions. | D27: Transversal | E27: Liste | F27: À intégrer / contrôler | G27: Matrice corpus + scénario détaillé | H27: IFAP
A28: CDC-024 | B28: 1.3 Principes rédactionnels | C28: Conservation aussi fidèle que possible des formulations expertes de Marie-Noëlle Lopez. | D28: Transversal | E28: Liste | F28: À intégrer / contrôler | G28: Matrice corpus + scénario détaillé | H28: IFAP
A29: CDC-025 | B29: 1.3 Principes rédactionnels | C29: Adaptations limitées aux corrections grammaticales, à la lisibilité numérique et aux nécessités de l’interaction. | D29: Transversal | E29: Liste | F29: À intégrer / contrôler | G29: Matrice corpus + scénario détaillé | H29: IFAP
... A208: CDC-204 | B208: 14. Documents de référence | C208: Charte graphique des modules des élus et règles d’usage du logo du Congrès. | D208: Transversal | E208: Liste | F208: À intégrer / contrôler | G208: Matrice corpus + scénario détaillé | H208: IFAP

Sheet 5_Contrôles
A1: Contrôles de couverture
A2: Contrôles automatiques à exécuter avant le scénario détaillé puis avant chaque prototype.
A4: Contrôle | B4: Résultat | C4: Attendu | D4: Écart | E4: Statut | F4: Action
A5: Nombre de documents sources | B5: 11 | C5: 11 | D5: =B5-C5 -> 0 | E5: =IF(D5=0,"OK","À corriger") -> OK | F5: Vérifier l’inventaire
A6: Nombre de blocs source | B6: 1079 | C6: 1079 | D6: =B6-C6 -> 0 | E6: =IF(D6=0,"OK","À corriger") -> OK | F6: Vérifier l’extraction
A7: Blocs sans séquence cible | B7: 0 | C7: 0 | D7: =B7-C7 -> 0 | E7: =IF(D7=0,"OK","À corriger") -> OK | F7: Affecter une cible
A8: Blocs sans transformation | B8: 0 | C8: 0 | D8: =B8-C8 -> 0 | E8: =IF(D8=0,"OK","À corriger") -> OK | F8: Définir un traitement
A9: Blocs nécessitant une adaptation obligatoire | B9: 104 | C9: Information | D9: — | E9: À valider | F9: Tracer les arbitrages
A10: Exigences CDC tracées | B10: 204 | C10: 204 | D10: =B10-C10 -> 0 | E10: =IF(D10=0,"OK","À corriger") -> OK | F10: Vérifier le cahier des charges
A13: Règles de transformation à appliquer au scénario détaillé
A14: 1 | B14: Intégrer d’abord l’intégralité du corpus au mot près ; élaguer seulement après validation explicite.
A15: 2 | B15: Conserver les intitulés techniques et les formulations expertes ; toute adaptation significative reste visible.
A16: 3 | B16: Utiliser les simulateurs uniquement lorsqu’ils servent une décision, une conséquence et une boucle réflexive complète.
A17: 4 | B17: Traiter les huit défis ; les priorités personnelles ne réduisent jamais le parcours.
A18: 5 | B18: Rendre le point de départ visible à la fin et produire une feuille de route exploitable.
A19: 6 | B19: Enrichir les cas et les personnages sans inventer d’affirmation professionnelle non validée.

Sheet 6_Couverture UX18I-N
A1: Couverture recalculée sur la version réellement livrée — candidate UX18I-N (MGT-55)
A2: Rapprochement automatique bloc par bloc avec le texte rendu des 59 écrans, les contenus dynamiques (JS) et les 6 fiches PDF. Méthode : feuille 9_Méthode.
A4: ID | B4: Module | C4: Séquence cible | D4: Fonction | E4: Texte source exact | F4: Statut dans la version livrée | G4: Similarité (0–1) | H4: Localisation dans le module | I4: Justification / exigence | J4: Validation IFAP / Marie-Noëlle
A5: MNL-0001 | B5: M0 | C5: Entrée + S6 — Comparaison finale | D5: Positionnement / boucle réflexive | E5: MODULE 0 — MON AUTO-POSITIONNEMENT DE MANAGER | F5: Conservé au mot près | G5: 1 | H5: PDF ecarts
A6: MNL-0002 | B6: M0 | C6: Entrée + S6 — Comparaison finale | D6: Positionnement / boucle réflexive | E6: Votre photographie de départ | F6: Conservé au mot près | G6: 1 | H6: écran g-pre
A7: MNL-0003 | B7: M0 | C7: Entrée + S6 — Comparaison finale | D7: Métadonnée de conception | E7: Fiche signalétique | F7: Conservé au mot près | G7: 1 | H7: PDF ecarts
A8: MNL-0004 | B8: M0 | C8: Entrée + S6 — Comparaison finale | D8: Métadonnée de conception | E8: Élément | Détail | F8: Non affiché — conception | G8: 0 | I8: Spécification ; non destinée à l’écran
A9: MNL-0005 | B9: M0 | C9: Entrée + S6 — Comparaison finale | D9: Métadonnée de conception | E9: Durée totale | 30 minutes maximum | F9: Non affiché — conception | G9: 0 | I9: Spécification ; non destinée à l’écran
A10: MNL-0006 | B10: M0 | C10: Entrée + S6 — Comparaison finale | D10: Métadonnée de conception | E10: Niveau atteint | Diagnostic | F10: Non affiché — conception | G10: 0 | I10: Spécification ; non destinée à l’écran
A11: MNL-0007 | B11: M0 | C11: Entrée + S6 — Comparaison finale | D11: Métadonnée de conception | E11: Prérequis | Aucun — module d'entrée dans le parcours | F11: Non affiché — conception | G11: 0.2 | I11: Spécification ; non destinée à l’écran
A12: MNL-0008 | B12: M0 | C12: Entrée + S6 — Comparaison finale | D12: Métadonnée de conception | E12: Indicateur mesurable | Score de profil managérial à T0 (référence pour la mesure finale, Module 7) | F12: Non affiché — conception | G12: 0 | I12: Spécification ; non destinée à l’écran
A13: MNL-0009 | B13: M0 | C13: Entrée + S6 — Comparaison finale | D13: Métadonnée de conception | E13: Condition de passage | Complétion de l'auto-positionnement — pas de bonne ou de mauvaise réponse ici, seule la complétude ouvre l'accès au Module 1 | F13: Non affiché — conception | G13: 0.05 | I13: Spécification ; non destinée à l’écran
A14: MNL-0010 | B14: M0 | C14: Entrée + S6 — Comparaison finale | D14: Métadonnée de conception | E14: Objectifs pédagogiques — à l'issue du module, l'apprenant(e) est capable de : Se situer sur les grandes dimensions qui seront travaillées tout au long du parcours ; Formuler une intention personnelle claire pour la suite de son parcours ; Comprendre la logique de progression du parcours, et ce qui l'attend module après module. | F14: Non affiché — conception | G14: 0.17 | I14: Spécification ; non destinée à l’écran
A15: MNL-0011 | B15: M0 | C15: Entrée + S6 — Comparaison finale | D15: Métadonnée de conception | E15: Séquençage (30 min) | F15: Conservé au mot près | G15: 1 | H15: PDF ecarts
A16: MNL-0012 | B16: M0 | C16: Entrée + S6 — Comparaison finale | D16: Métadonnée de conception | E16: # | Étape | Durée | Modalité | F16: Non affiché — conception | G16: 0 | I16: Spécification ; non destinée à l’écran
A17: MNL-0013 | B17: M0 | C17: Entrée + S6 — Comparaison finale | D17: Métadonnée de conception | E17: 0 | Scénario d'ouverture (vidéo, dialogue avant / après) | 2 min | Vidéo | F17: Non affiché — conception | G17: 0 | I17: Spécification ; non destinée à l’écran
A18: MNL-0014 | B18: M0 | C18: Entrée + S6 — Comparaison finale | D18: Métadonnée de conception | E18: 1 | Pourquoi ce point de départ compte | 3 min | Contenu court | F18: Non affiché — conception | G18: 0.38 | H18: écran g-pre | I18: Spécification ; non destinée à l’écran
A19: MNL-0015 | B19: M0 | C19: Entrée + S6 — Comparaison finale | D19: Métadonnée de conception | E19: 2 | Votre auto-positionnement, en 6 dimensions | 15 min | Quiz interactif | F19: Non affiché — conception | G19: 0.5 | H19: PDF ecarts | I19: Spécification ; non destinée à l’écran
A20: MNL-0016 | B20: M0 | C20: Entrée + S6 — Comparaison finale | D20: Métadonnée de conception | E20: 3 | Votre photographie de départ | 4 min | Restitution visuelle | F20: Conservé au mot près | G20: 1 | H20: PDF ecarts
A21: MNL-0017 | B21: M0 | C21: Entrée — Contrat pédagogique | D21: Métadonnée de conception | E21: 4 | Une intention pour votre parcours | 4 min | Réponse libre | F21: Conservé au mot près | G21: 1 | H21: PDF ecarts
A22: MNL-0018 | B22: M0 | C22: Entrée + S6 — Comparaison finale | D22: Métadonnée de conception | E22: 5 | Ce qui vous attend | 2 min | Repère de progression | F22: Non affiché — conception | G22: 0.14 | I22: Spécification ; non destinée à l’écran
A23: MNL-0019 | B23: M0 | C23: Entrée + S6 — Comparaison finale | D23: Métadonnée de conception | E23: 0. Scénario d'ouverture — script pour vidéo IA (dialogue avant / après) | F23: Non affiché — conception | G23: 0 | I23: Spécification ; non destinée à l’écran
A24: MNL-0020 | B24: M0 | C24: Entrée + S6 — Comparaison finale | D24: Métadonnée de conception | E24: Durée cible : 60-75 secondes. Ton : chaleureux, incarné. Cette scène n'illustre pas un seul module, mais l'ensemble du parcours — c'est la bande-annonce, pas une leçon. | F24: Non affiché — conception | G24: 0.04 | I24: Spécification ; non destinée à l’écran
A25: MNL-0021 | B25: M0 | C25: Entrée + S6 — Comparaison finale | D25: Métadonnée de conception | E25: Personnages : un(e) élu(e), et un(e) collaborateur(trice). Décor unique : un bureau. | F25: Non affiché — conception | G25: 0.33 | H25: PDF ecarts | I25: Spécification ; non destinée à l’écran
A26: MNL-0022 | B26: M0 | C26: Entrée + S6 — Comparaison finale | D26: Métadonnée de conception | E26: Scène 1 — Aujourd'hui, peut-être. | F26: Non affiché — conception | G26: 0 | I26: Spécification ; non destinée à l’écran
A27: MNL-0023 | B27: M0 | C27: Entrée + S6 — Comparaison finale | D27: Métadonnée de conception | E27: L'élu(e), débordé(e), plusieurs dossiers ouverts en même temps, répond au téléphone tout en parcourant un document. Un(e) collaborateur(trice) entre, hésite, repart sans avoir posé sa question. | F27: Non affiché — conception | G27: 0.07 | I27: Spécification ; non destinée à l’écran
A28: MNL-0024 | B28: M0 | C28: Entrée + S6 — Comparaison finale | D28: Métadonnée de conception | E28: Élu(e), au téléphone, essoufflé(e) : « Oui, je regarde ça... non, pas encore, je reviens vers vous... » | F28: Non affiché — conception | G28: 0.33 | H28: écran mod-s1-02 | I28: Spécification ; non destinée à l’écran
A29: MNL-0025 | B29: M0 | C29: Entrée + S6 — Comparaison finale | D29: Métadonnée de conception | E29: Bascule à l'écran : « Et si, quelques mois plus tard... » | F29: Non affiché — conception | G29: 0.57 | H29: PDF ecarts | I29: Spécification ; non destinée à l’écran
A30: MNL-0026 | B30: M0 | C30: Entrée + S6 — Comparaison finale | D30: Métadonnée de conception | E30: Scène 2 — Plus tard dans le mandat. | F30: Non affiché — conception | G30: 0.4 | H30: écran g-pre | I30: Spécification ; non destinée à l’écran
A31: MNL-0027 | B31: M0 | C31: Entrée + S6 — Comparaison finale | D31: Métadonnée de conception | E31: Même bureau, même élu(e) — mais le rythme a changé. Le/la collaborateur(trice) entre, pose une question précise. | F31: Non affiché — conception | G31: 0.12 | I31: Spécification ; non destinée à l’écran
A32: MNL-0028 | B32: M0 | C32: Entrée + S6 — Comparaison finale | D32: Métadonnée de conception | E32: Collaborateur(trice) : « J'ai une proposition pour le dossier, vous voulez qu'on en parle deux minutes ? » | F32: Non affiché — conception | G32: 0.15 | I32: Spécification ; non destinée à l’écran
A33: MNL-0029 | B33: M0 | C33: Entrée + S6 — Comparaison finale | D33: Métadonnée de conception | E33: Élu(e), disponible, pose ce qu'il/elle faisait : « Allez-y, je vous écoute. » | F33: Non affiché — conception | G33: 0.09 | I33: Spécification ; non destinée à l’écran
A34: MNL-0030 | B34: M0 | C34: Entrée + S6 — Comparaison finale | D34: Métadonnée de conception | E34: Voix off : “Entre ces deux scènes, rien n'a changé dans la charge du mandat. Ce qui a changé, ce sont quelques réflexes — de posture, de communication, de délégation.” | F34: Non affiché — conception | G34: 0.08 | I34: Spécification ; non destinée à l’écran
A35: MNL-0031 | B35: M0 | C35: Entrée + S6 — Comparaison finale | D35: Métadonnée de conception | E35: Ce parcours ne vous demande pas de devenir quelqu'un d'autre. Il vous donne des repères simples pour retrouver, dans votre quotidien, un peu plus de la seconde scène. Avant de commencer, prenons une photographie de là où vous en êtes aujourd'hui | F35: Non affiché — conception | G35: 0.26 | I35: Spécification ; non destinée à l’écran
A36: MNL-0032 | B36: M0 | C36: Entrée + S6 — Comparaison finale | D36: Structuration | E36: 1. Pourquoi ce point de départ compte | F36: Conservé avec adaptation | G36: 0.75 | H36: écran g-pre
A37: MNL-0033 | B37: M0 | C37: Entrée + S6 — Comparaison finale | D37: Structuration | E37: On ajuste mieux ce que l'on a d'abord regardé en face. | F37: Conservé au mot près | G37: 1 | H37: PDF ecarts
A38: MNL-0034 | B38: M0 | C38: Entrée + S6 — Comparaison finale | D38: Apport / message pédagogique | E38: Ce premier module ne vous apprend rien de nouveau. Il vous propose un temps court pour observer, sincèrement, où vous en êtes aujourd'hui sur les grandes dimensions du management d'équipe — avant que le parcours ne les travaille une à une. | F38: Conservé au mot près | G38: 1 | H38: PDF ecarts
A39: MNL-0035 | B39: M0 | C39: Entrée + S6 — Comparaison finale | D39: Référence / fondement | E39: Les références | F39: Modifié / arbitré (CDC) | G39: 0 | I39: MGT-10 — intitulé remplacé par l’accordéon « Source »
A40: MNL-0036 | B40: M0 | C40: Entrée + S6 — Comparaison finale | D40: Référence / fondement | E40: Un repère qui vient de la recherche sur la motivation et les objectifs Les travaux d'Edwin Locke et Gary Latham, menés sur plusieurs décennies et régulièrement confirmés depuis, montrent qu'un objectif clair, formulé précisément et choisi par la personne elle-même, produit un engagement et une progression plus solides qu'une intention vague ou imposée de l'extérieur. Se donner un point de départ précis n'est donc pas un exercice administratif : c'est ce qui rend la suite du parcours plus efficace. (Repère issu de la recherche en psychologie du travail. Référence : Locke, E. A., & Latham, G. P. (2002). Building a practically useful theory of goal setting and task motivation. American Psychologist, 57(9), 705-717.) | F40: Conservé au mot près | G40: 1 | H40: PDF ecarts
A41: MNL-0037 | B41: M0 | C41: Entrée + S6 — Comparaison finale | D41: Apport structuré | E41: Ce que l'on peut en retenir — Ce score de départ n'évalue rien, ne juge personne, et ne sera comparé à celui de personne d'autre. Il vous appartient, et il n'a qu'un seul usage : vous permettre, à la fin du parcours, de mesurer votre propre chemin | F41: Conservé au mot près | G41: 1 | H41: écran g-pre
...

Sheet 7_Synthèse livrée
A1: Synthèse de couverture — version livrée UX18I-N
A2: Les valeurs sont calculées par formules à partir de la feuille 6 : elles se mettent à jour si un statut est corrigé.
A4: Séquence cible | B4: Conservé au mot près | C4: Conservé avec adaptation | D4: Condensé / transformé — à vérifier | E4: Modifié / arbitré (CDC) | F4: Adaptation obligatoire (CDC) | G4: Non retrouvé — à réintégrer | H4: Non affiché — conception | I4: Structure fusionnée | J4: Blocs significatifs | K4: Couverture expliquée (%) | L4: Conservé (mot + adaptation) (%)
A5: Entrée + S6 — Comparaison finale | B5: =COUNTIFS('6_Couverture UX18I-N'!$C$5:$C$1083,$A5,'6_Couverture UX18I-N'!$F$5:$F$1083,"Conservé au mot près") -> 33 | C5: =COUNTIFS('6_Couverture UX18I-N'!$C$5:$C$1083,$A5,'6_Couverture UX18I-N'!$F$5:$F$1083,"Conservé avec adaptation") -> 2 | D5: =COUNTIFS('6_Couverture UX18I-N'!$C$5:$C$1083,$A5,'6_Couverture UX18I-N'!$F$5:$F$1083,"Condensé / transformé — à vérifier") -> 0 | E5: =COUNTIFS('6_Couverture UX18I-N'!$C$5:$C$1083,$A5,'6_Couverture UX18I-N'!$F$5:$F$1083,"Modifié / arbitré (CDC)") -> 1 | F5: =COUNTIFS('6_Couverture UX18I-N'!$C$5:$C$1083,$A5,'6_Couverture UX18I-N'!$F$5:$F$1083,"Adaptation obligatoire (CDC)") -> 0 | G5: =COUNTIFS('6_Couverture UX18I-N'!$C$5:$C$1083,$A5,'6_Couverture UX18I-N'!$F$5:$F$1083,"Non retrouvé — à réintégrer") -> 0 | H5: =COUNTIFS('6_Couverture UX18I-N'!$C$5:$C$1083,$A5,'6_Couverture UX18I-N'!$F$5:$F$1083,"Non affiché — conception") -> 26 | I5: =COUNTIFS('6_Couverture UX18I-N'!$C$5:$C$1083,$A5,'6_Couverture UX18I-N'!$F$5:$F$1083,"Structure fusionnée") -> 0 | J5: =SUM(B5:G5) -> 36 | K5: =IF(J5=0,"",(J5-G5)/J5) -> 1 | L5: =IF(J5=0,"",(B5+C5)/J5) -> 0.97222222
A6: Entrée — Contrat pédagogique | B6: =COUNTIFS('6_Couverture UX18I-N'!$C$5:$C$1083,$A6,'6_Couverture UX18I-N'!$F$5:$F$1083,"Conservé au mot près") -> 13 | C6: =COUNTIFS('6_Couverture UX18I-N'!$C$5:$C$1083,$A6,'6_Couverture UX18I-N'!$F$5:$F$1083,"Conservé avec adaptation") -> 0 | D6: =COUNTIFS('6_Couverture UX18I-N'!$C$5:$C$1083,$A6,'6_Couverture UX18I-N'!$F$5:$F$1083,"Condensé / transformé — à vérifier") -> 0 | E6: =COUNTIFS('6_Couverture UX18I-N'!$C$5:$C$1083,$A6,'6_Couverture UX18I-N'!$F$5:$F$1083,"Modifié / arbitré (CDC)") -> 0 | F6: =COUNTIFS('6_Couverture UX18I-N'!$C$5:$C$1083,$A6,'6_Couverture UX18I-N'!$F$5:$F$1083,"Adaptation obligatoire (CDC)") -> 0 | G6: =COUNTIFS('6_Couverture UX18I-N'!$C$5:$C$1083,$A6,'6_Couverture UX18I-N'!$F$5:$F$1083,"Non retrouvé — à réintégrer") -> 0 | H6: =COUNTIFS('6_Couverture UX18I-N'!$C$5:$C$1083,$A6,'6_Couverture UX18I-N'!$F$5:$F$1083,"Non affiché — conception") -> 2 | I6: =COUNTIFS('6_Couverture UX18I-N'!$C$5:$C$1083,$A6,'6_Couverture UX18I-N'!$F$5:$F$1083,"Structure fusionnée") -> 0 | J6: =SUM(B6:G6) -> 13 | K6: =IF(J6=0,"",(J6-G6)/J6) -> 1 | L6: =IF(J6=0,"",(B6+C6)/J6) -> 1
A7: S1 — Prendre ma place de manager | B7: =COUNTIFS('6_Couverture UX18I-N'!$C$5:$C$1083,$A7,'6_Couverture UX18I-N'!$F$5:$F$1083,"Conservé au mot près") -> 153 | C7: =COUNTIFS('6_Couverture UX18I-N'!$C$5:$C$1083,$A7,'6_Couverture UX18I-N'!$F$5:$F$1083,"Conservé avec adaptation") -> 11 | D7: =COUNTIFS('6_Couverture UX18I-N'!$C$5:$C$1083,$A7,'6_Couverture UX18I-N'!$F$5:$F$1083,"Condensé / transformé — à vérifier") -> 0 | E7: =COUNTIFS('6_Couverture UX18I-N'!$C$5:$C$1083,$A7,'6_Couverture UX18I-N'!$F$5:$F$1083,"Modifié / arbitré (CDC)") -> 32 | F7: =COUNTIFS('6_Couverture UX18I-N'!$C$5:$C$1083,$A7,'6_Couverture UX18I-N'!$F$5:$F$1083,"Adaptation obligatoire (CDC)") -> 11 | G7: =COUNTIFS('6_Couverture UX18I-N'!$C$5:$C$1083,$A7,'6_Couverture UX18I-N'!$F$5:$F$1083,"Non retrouvé — à réintégrer") -> 0 | H7: =COUNTIFS('6_Couverture UX18I-N'!$C$5:$C$1083,$A7,'6_Couverture UX18I-N'!$F$5:$F$1083,"Non affiché — conception") -> 50 | I7: =COUNTIFS('6_Couverture UX18I-N'!$C$5:$C$1083,$A7,'6_Couverture UX18I-N'!$F$5:$F$1083,"Structure fusionnée") -> 5 | J7: =SUM(B7:G7) -> 207 | K7: =IF(J7=0,"",(J7-G7)/J7) -> 1 | L7: =IF(J7=0,"",(B7+C7)/J7) -> 0.79227053
A8: S2 — Construire une équipe sur laquelle je peux m’appuyer | B8: =COUNTIFS('6_Couverture UX18I-N'!$C$5:$C$1083,$A8,'6_Couverture UX18I-N'!$F$5:$F$1083,"Conservé au mot près") -> 65 | C8: =COUNTIFS('6_Couverture UX18I-N'!$C$5:$C$1083,$A8,'6_Couverture UX18I-N'!$F$5:$F$1083,"Conservé avec adaptation") -> 4 | D8: =COUNTIFS('6_Couverture UX18I-N'!$C$5:$C$1083,$A8,'6_Couverture UX18I-N'!$F$5:$F$1083,"Condensé / transformé — à vérifier") -> 0 | E8: =COUNTIFS('6_Couverture UX18I-N'!$C$5:$C$1083,$A8,'6_Couverture UX18I-N'!$F$5:$F$1083,"Modifié / arbitré (CDC)") -> 12 | F8: =COUNTIFS('6_Couverture UX18I-N'!$C$5:$C$1083,$A8,'6_Couverture UX18I-N'!$F$5:$F$1083,"Adaptation obligatoire (CDC)") -> 2 | G8: =COUNTIFS('6_Couverture UX18I-N'!$C$5:$C$1083,$A8,'6_Couverture UX18I-N'!$F$5:$F$1083,"Non retrouvé — à réintégrer") -> 0 | H8: =COUNTIFS('6_Couverture UX18I-N'!$C$5:$C$1083,$A8,'6_Couverture UX18I-N'!$F$5:$F$1083,"Non affiché — conception") -> 33 | I8: =COUNTIFS('6_Couverture UX18I-N'!$C$5:$C$1083,$A8,'6_Couverture UX18I-N'!$F$5:$F$1083,"Structure fusionnée") -> 5 | J8: =SUM(B8:G8) -> 83 | K8: =IF(J8=0,"",(J8-G8)/J8) -> 1 | L8: =IF(J8=0,"",(B8+C8)/J8) -> 0.8313253
A9: S4 — Faire grandir l’autonomie et l’engagement | B9: =COUNTIFS('6_Couverture UX18I-N'!$C$5:$C$1083,$A9,'6_Couverture UX18I-N'!$F$5:$F$1083,"Conservé au mot près") -> 87 | C9: =COUNTIFS('6_Couverture UX18I-N'!$C$5:$C$1083,$A9,'6_Couverture UX18I-N'!$F$5:$F$1083,"Conservé avec adaptation") -> 3 | D9: =COUNTIFS('6_Couverture UX18I-N'!$C$5:$C$1083,$A9,'6_Couverture UX18I-N'!$F$5:$F$1083,"Condensé / transformé — à vérifier") -> 0 | E9: =COUNTIFS('6_Couverture UX18I-N'!$C$5:$C$1083,$A9,'6_Couverture UX18I-N'!$F$5:$F$1083,"Modifié / arbitré (CDC)") -> 15 | F9: =COUNTIFS('6_Couverture UX18I-N'!$C$5:$C$1083,$A9,'6_Couverture UX18I-N'!$F$5:$F$1083,"Adaptation obligatoire (CDC)") -> 2 | G9: =COUNTIFS('6_Couverture UX18I-N'!$C$5:$C$1083,$A9,'6_Couverture UX18I-N'!$F$5:$F$1083,"Non retrouvé — à réintégrer") -> 0 | H9: =COUNTIFS('6_Couverture UX18I-N'!$C$5:$C$1083,$A9,'6_Couverture UX18I-N'!$F$5:$F$1083,"Non affiché — conception") -> 33 | I9: =COUNTIFS('6_Couverture UX18I-N'!$C$5:$C$1083,$A9,'6_Couverture UX18I-N'!$F$5:$F$1083,"Structure fusionnée") -> 1 | J9: =SUM(B9:G9) -> 107 | K9: =IF(J9=0,"",(J9-G9)/J9) -> 1 | L9: =IF(J9=0,"",(B9+C9)/J9) -> 0.8411215
A10: S3 — Faire comprendre ce que j’attends | B10: =COUNTIFS('6_Couverture UX18I-N'!$C$5:$C$1083,$A10,'6_Couverture UX18I-N'!$F$5:$F$1083,"Conservé au mot près") -> 111 | C10: =COUNTIFS('6_Couverture UX18I-N'!$C$5:$C$1083,$A10,'6_Couverture UX18I-N'!$F$5:$F$1083,"Conservé avec adaptation") -> 8 | D10: =COUNTIFS('6_Couverture UX18I-N'!$C$5:$C$1083,$A10,'6_Couverture UX18I-N'!$F$5:$F$1083,"Condensé / transformé — à vérifier") -> 0 | E10: =COUNTIFS('6_Couverture UX18I-N'!$C$5:$C$1083,$A10,'6_Couverture UX18I-N'!$F$5:$F$1083,"Modifié / arbitré (CDC)") -> 14 | F10: =COUNTIFS('6_Couverture UX18I-N'!$C$5:$C$1083,$A10,'6_Couverture UX18I-N'!$F$5:$F$1083,"Adaptation obligatoire (CDC)") -> 1 | G10: =COUNTIFS('6_Couverture UX18I-N'!$C$5:$C$1083,$A10,'6_Couverture UX18I-N'!$F$5:$F$1083,"Non retrouvé — à réintégrer") -> 0 | H10: =COUNTIFS('6_Couverture UX18I-N'!$C$5:$C$1083,$A10,'6_Couverture UX18I-N'!$F$5:$F$1083,"Non affiché — conception") -> 37 | I10: =COUNTIFS('6_Couverture UX18I-N'!$C$5:$C$1083,$A10,'6_Couverture UX18I-N'!$F$5:$F$1083,"Structure fusionnée") -> 1 | J10: =SUM(B10:G10) -> 134 | K10: =IF(J10=0,"",(J10-G10)/J10) -> 1 | L10: =IF(J10=0,"",(B10+C10)/J10) -> 0.8880597
A11: S5 — Préserver la relation dans les moments difficiles | B11: =COUNTIFS('6_Couverture UX18I-N'!$C$5:$C$1083,$A11,'6_Couverture UX18I-N'!$F$5:$F$1083,"Conservé au mot près") -> 116 | C11: =COUNTIFS('6_Couverture UX18I-N'!$C$5:$C$1083,$A11,'6_Couverture UX18I-N'!$F$5:$F$1083,"Conservé avec adaptation") -> 4 | D11: =COUNTIFS('6_Couverture UX18I-N'!$C$5:$C$1083,$A11,'6_Couverture UX18I-N'!$F$5:$F$1083,"Condensé / transformé — à vérifier") -> 0 | E11: =COUNTIFS('6_Couverture UX18I-N'!$C$5:$C$1083,$A11,'6_Couverture UX18I-N'!$F$5:$F$1083,"Modifié / arbitré (CDC)") -> 15 | F11: =COUNTIFS('6_Couverture UX18I-N'!$C$5:$C$1083,$A11,'6_Couverture UX18I-N'!$F$5:$F$1083,"Adaptation obligatoire (CDC)") -> 2 | G11: =COUNTIFS('6_Couverture UX18I-N'!$C$5:$C$1083,$A11,'6_Couverture UX18I-N'!$F$5:$F$1083,"Non retrouvé — à réintégrer") -> 0 | H11: =COUNTIFS('6_Couverture UX18I-N'!$C$5:$C$1083,$A11,'6_Couverture UX18I-N'!$F$5:$F$1083,"Non affiché — conception") -> 57 | I11: =COUNTIFS('6_Couverture UX18I-N'!$C$5:$C$1083,$A11,'6_Couverture UX18I-N'!$F$5:$F$1083,"Structure fusionnée") -> 1 | J11: =SUM(B11:G11) -> 137 | K11: =IF(J11=0,"",(J11-G11)/J11) -> 1 | L11: =IF(J11=0,"",(B11+C11)/J11) -> 0.87591241
A12: S6 — Faire évoluer ma pratique | B12: =COUNTIFS('6_Couverture UX18I-N'!$C$5:$C$1083,$A12,'6_Couverture UX18I-N'!$F$5:$F$1083,"Conservé au mot près") -> 39 | C12: =COUNTIFS('6_Couverture UX18I-N'!$C$5:$C$1083,$A12,'6_Couverture UX18I-N'!$F$5:$F$1083,"Conservé avec adaptation") -> 1 | D12: =COUNTIFS('6_Couverture UX18I-N'!$C$5:$C$1083,$A12,'6_Couverture UX18I-N'!$F$5:$F$1083,"Condensé / transformé — à vérifier") -> 0 | E12: =COUNTIFS('6_Couverture UX18I-N'!$C$5:$C$1083,$A12,'6_Couverture UX18I-N'!$F$5:$F$1083,"Modifié / arbitré (CDC)") -> 1 | F12: =COUNTIFS('6_Couverture UX18I-N'!$C$5:$C$1083,$A12,'6_Couverture UX18I-N'!$F$5:$F$1083,"Adaptation obligatoire (CDC)") -> 0 | G12: =COUNTIFS('6_Couverture UX18I-N'!$C$5:$C$1083,$A12,'6_Couverture UX18I-N'!$F$5:$F$1083,"Non retrouvé — à réintégrer") -> 0 | H12: =COUNTIFS('6_Couverture UX18I-N'!$C$5:$C$1083,$A12,'6_Couverture UX18I-N'!$F$5:$F$1083,"Non affiché — conception") -> 31 | I12: =COUNTIFS('6_Couverture UX18I-N'!$C$5:$C$1083,$A12,'6_Couverture UX18I-N'!$F$5:$F$1083,"Structure fusionnée") -> 3 | J12: =SUM(B12:G12) -> 41 | K12: =IF(J12=0,"",(J12-G12)/J12) -> 1 | L12: =IF(J12=0,"",(B12+C12)/J12) -> 0.97560976
A13: Entrée — Bienvenue | B13: =COUNTIFS('6_Couverture UX18I-N'!$C$5:$C$1083,$A13,'6_Couverture UX18I-N'!$F$5:$F$1083,"Conservé au mot près") -> 31 | C13: =COUNTIFS('6_Couverture UX18I-N'!$C$5:$C$1083,$A13,'6_Couverture UX18I-N'!$F$5:$F$1083,"Conservé avec adaptation") -> 2 | D13: =COUNTIFS('6_Couverture UX18I-N'!$C$5:$C$1083,$A13,'6_Couverture UX18I-N'!$F$5:$F$1083,"Condensé / transformé — à vérifier") -> 0 | E13: =COUNTIFS('6_Couverture UX18I-N'!$C$5:$C$1083,$A13,'6_Couverture UX18I-N'!$F$5:$F$1083,"Modifié / arbitré (CDC)") -> 2 | F13: =COUNTIFS('6_Couverture UX18I-N'!$C$5:$C$1083,$A13,'6_Couverture UX18I-N'!$F$5:$F$1083,"Adaptation obligatoire (CDC)") -> 0 | G13: =COUNTIFS('6_Couverture UX18I-N'!$C$5:$C$1083,$A13,'6_Couverture UX18I-N'!$F$5:$F$1083,"Non retrouvé — à réintégrer") -> 0 | H13: =COUNTIFS('6_Couverture UX18I-N'!$C$5:$C$1083,$A13,'6_Couverture UX18I-N'!$F$5:$F$1083,"Non affiché — conception") -> 0 | I13: =COUNTIFS('6_Couverture UX18I-N'!$C$5:$C$1083,$A13,'6_Couverture UX18I-N'!$F$5:$F$1083,"Structure fusionnée") -> 1 | J13: =SUM(B13:G13) -> 35 | K13: =IF(J13=0,"",(J13-G13)/J13) -> 1 | L13: =IF(J13=0,"",(B13+C13)/J13) -> 0.94285714
A14: TOTAL | B14: =SUM(B5:B13) -> 648 | C14: =SUM(C5:C13) -> 35 | D14: =SUM(D5:D13) -> 0 | E14: =SUM(E5:E13) -> 92 | F14: =SUM(F5:F13) -> 18 | G14: =SUM(G5:G13) -> 0 | H14: =SUM(H5:H13) -> 269 | I14: =SUM(I5:I13) -> 17 | J14: =SUM(B14:G14) -> 793 | K14: =IF(J14=0,"",(J14-G14)/J14) -> 1 | L14: =IF(J14=0,"",(B14+C14)/J14) -> 0.86128625

Sheet 8_À vérifier
A1: Blocs présents sous une forme condensée ou transformée — lecture humaine recommandée
A2: Plus aucun bloc significatif n’est absent : ces blocs sont présents, mais avec un écart de formulation à confirmer.
A4: ID | B4: Séquence cible | C4: Module | D4: Fonction | E4: Texte source exact | F4: Similarité | G4: Décision
A5: Aucun bloc : tous les blocs significatifs sont conservés ou arbitrés.

Sheet 9_Méthode
A1: Méthode de recalcul (MGT-55)
A3: 1. Texte du module extrait de la version livrée : texte rendu de chaque écran (69), chaînes des contenus dynamiques (JS), texte des 6 fiches PDF. L’écran retiré mod-s1-04b, masqué, est exclu.
A4: 2. Pour chaque bloc, le texte source est normalisé (casse, apostrophes, ponctuation) ; les marqueurs de maquette sont neutralisés : « a) b) c) », « (bonne réponse) », « (Champ de réponse libre) », numérotation, libellés « Objectif — », « Concept — »…
A5: 3. Similarité = part des triplets de mots du bloc retrouvés dans un même emplacement du module (paires pour les blocs de 2–3 mots). On retient le meilleur emplacement.
A6: 4. Seuils : ≥ 0,85 conservé au mot près ; 0,55–0,85 conservé avec adaptation ; 0,30–0,55 condensé / transformé — à vérifier par lecture humaine.
A7: 5. Sous 0,30 : statut explicatif si le bloc relève d’un arbitrage CDC (instantanés, petits bilans, « Repère du corpus », intitulé « Les références », MGT-12), d’une métadonnée de conception (fiche signalétique, séquençage, scripts vidéo, infos internes), d’un intitulé de structure absorbé par les 6 repères, ou d’une « Adaptation obligatoire » prévue par la matrice ; sinon « Non retrouvé — à réintégrer ».
A8: 6. Limite : une reformulation fidèle mais lexicalement éloignée peut être classée « non retrouvée ». La colonne Validation permet de corriger le statut ; la synthèse 7 se recalcule.
A9: 7. Les feuilles 0 à 5 de la matrice d’origine sont inchangées.
